class MyException(n: Int) extends Exception

@debug
memoized fun throwValue(n: Int): void {
  print_string("throwValue " + n);
  throw MyException(n)
}

fun main(): void {
  msg = "Pass ";

  Range(0, 3).each(i -> {
    try {
      throwValue(i % 2)
    } catch {
    | MyException(n) -> !msg = msg + n
    }
  });

  print_raw(msg + "\n")
}
