File "tests/runtime/invalid/try_catch_return_1.sk", line 4, characters 7-18:
Forbidden use of 'return' inside a 'try ... catch'.
2 |   print_raw(
3 |     try {
4 |       return "Foo"
  |       ^^^^^^^^^^^^
5 |     } catch {
